Workbook

Sheet Respuestas de formulario 1
A1: Marca temporal | B1: Apellido | C1: Nombre | D1: e-mail | E1: Fecha de nacimiento | F1: DNI | G1: Teléfono | H1: ¿Cómo nos encontraste? | I1: ¿Cómo te vas a atender? | J1: ¿Cuál es tu obra social? | K1: ¿Realizás actividad física? | L1: ¿Qué actividad física realizás? | M1: ¿Cuántas veces por semana entrenás? | N1: ¿Cómo te vas a atender? | O1: ¿Cuál es tu obra social? | Q1: ¿Realizás activad física? | R1: FUENTE | S1: AÑO | T1: MES
A2: 44865.663 | B2: Llanos | C2: Cristian | D2: Cristian_kobe@hotmail.com | E2: 31427 | F2: 32099118 | G2: 3518046736 | H2: Google | I2: Obra social | J2: APROSS | R2: =IF(H2="","",VLOOKUP(H2,'Hoja 9'!$A$1:$B$255,2,0)) -> GOOGLE | S2: =IF(A2="","",YEAR(A2)) -> 2022 | T2: =IF(A2="","",MONTH(A2)) -> 10
A3: 44866.425 | B3: Leiva | C3: Nilda Carolina | D3: caroagus023@gmail.com | E3: 29208 | F3: 27671982 | G3: 3513844529 | H3: Recomendación | I3: Particular | R3: =IF(H3="","",VLOOKUP(H3,'Hoja 9'!$A$1:$B$255,2,0)) -> BOCA EN BOCA | S3: =IF(A3="","",YEAR(A3)) -> 2022 | T3: =IF(A3="","",MONTH(A3)) -> 11
A4: 44872.859 | B4: Far | C4: Juan Manuel | D4: Manufar87@hotmail.com | E4: 31894 | F4: 33082576 | G4: 3512006711 | H4: Recomendación | I4: Particular | R4: =IF(H4="","",VLOOKUP(H4,'Hoja 9'!$A$1:$B$255,2,0)) -> BOCA EN BOCA | S4: =IF(A4="","",YEAR(A4)) -> 2022 | T4: =IF(A4="","",MONTH(A4)) -> 11
A5: 44879.654 | B5: Urquía | C5: Yohana | D5: yohana.urquia@gmail.com | E5: 31206 | F5: 31647631 | G5: 3516299562 | H5: Recomendación | I5: Particular | R5: =IF(H5="","",VLOOKUP(H5,'Hoja 9'!$A$1:$B$255,2,0)) -> BOCA EN BOCA | S5: =IF(A5="","",YEAR(A5)) -> 2022 | T5: =IF(A5="","",MONTH(A5)) -> 11
A6: 44879.671 | B6: Lopez | C6: Gonzalo Daniel | D6: Zonlopez10@gmail.com | E6: 34623 | F6: 38501250 | G6: 3515186768 | H6: Lo conozco al fabri de defensores | I6: Obra social | J6: APROSS | R6: =IF(H6="","",VLOOKUP(H6,'Hoja 9'!$A$1:$B$255,2,0)) -> BOCA EN BOCA | S6: =IF(A6="","",YEAR(A6)) -> 2022 | T6: =IF(A6="","",MONTH(A6)) -> 11
A7: 44880.471 | B7: Agüero | C7: Juan Manuel | D7: juanmamendiolaza@gmail.com | E7: 31846 | F7: 32787354 | G7: 3516219534 | H7: Google | I7: Particular | R7: =IF(H7="","",VLOOKUP(H7,'Hoja 9'!$A$1:$B$255,2,0)) -> GOOGLE | S7: =IF(A7="","",YEAR(A7)) -> 2022 | T7: =IF(A7="","",MONTH(A7)) -> 11
A8: 44880.5 | B8: Valdez | C8: Rubén | D8: Rubenavaldez930@gmail.com | E8: 34161 | F8: 37733188 | G8: 3513374771 | H8: Voy al gym Manantial | J8: APROSS | R8: =IF(H8="","",VLOOKUP(H8,'Hoja 9'!$A$1:$B$255,2,0)) -> GIMNASIO | S8: =IF(A8="","",YEAR(A8)) -> 2022 | T8: =IF(A8="","",MONTH(A8)) -> 11
A9: 44881.413 | B9: Giménez | C9: Fernando | D9: gimenezfa@gmail.com | E9: 35171 | F9: 30544064 | G9: 3516953672 | H9: Recomendación | I9: Obra social | J9: APROSS | R9: =IF(H9="","",VLOOKUP(H9,'Hoja 9'!$A$1:$B$255,2,0)) -> BOCA EN BOCA | S9: =IF(A9="","",YEAR(A9)) -> 2022 | T9: =IF(A9="","",MONTH(A9)) -> 11
A10: 44881.491 | B10: JOHNSON | C10: GUILLERMO | D10: guillermorjohnson@gmail.com | E10: 26996 | F10: 23683982 | G10: 3515138062 | H10: Recomendación | I10: Obra social | J10: caja Notarial | R10: =IF(H10="","",VLOOKUP(H10,'Hoja 9'!$A$1:$B$255,2,0)) -> BOCA EN BOCA | S10: =IF(A10="","",YEAR(A10)) -> 2022 | T10: =IF(A10="","",MONTH(A10)) -> 11
A11: 44881.688 | B11: Carnevale | C11: Mariela | D11: marielacarnevale533@hotmail.com | E11: 29629 | F11: 23683982 | G11: 3513040216 | H11: Google | I11: Particular | R11: =IF(H11="","",VLOOKUP(H11,'Hoja 9'!$A$1:$B$255,2,0)) -> GOOGLE | S11: =IF(A11="","",YEAR(A11)) -> 2022 | T11: =IF(A11="","",MONTH(A11)) -> 11
A12: 44882.46 | B12: Isa Minuet | C12: Elías | D12: eliasisaa@gmail.com | E12: 36108 | F12: 41019335 | G12: 3517580512 | H12: Voy al gym Manantial | I12: Obra social | J12: SANCOR | R12: =IF(H12="","",VLOOKUP(H12,'Hoja 9'!$A$1:$B$255,2,0)) -> GIMNASIO | S12: =IF(A12="","",YEAR(A12)) -> 2022 | T12: =IF(A12="","",MONTH(A12)) -> 11
A13: 44888.414 | B13: Ghibaudo | C13: Pablo | D13: lic.pabloghibaudo@gmail.com | E13: 29137 | F13: 27267620 | G13: 3515528353 | H13: Google | I13: Obra social | J13: APROSS | R13: =IF(H13="","",VLOOKUP(H13,'Hoja 9'!$A$1:$B$255,2,0)) -> GOOGLE | S13: =IF(A13="","",YEAR(A13)) -> 2022 | T13: =IF(A13="","",MONTH(A13)) -> 11
A14: 44889.821 | B14: Asinari | C14: Emanuel | D14: lic.pabloghibaudo@gmail.com | E14: 34338 | F14: 38001813 | G14: 3516098550 | H14: Soy amigo de la feliz pareja | I14: Particular | R14: =IF(H14="","",VLOOKUP(H14,'Hoja 9'!$A$1:$B$255,2,0)) -> BOCA EN BOCA | S14: =IF(A14="","",YEAR(A14)) -> 2022 | T14: =IF(A14="","",MONTH(A14)) -> 11
A15: 44890.799 | B15: Rivara | C15: Mauro Alejandro | D15: rivaramauro@hotmail.com | E15: 22514 | F15: 14747390 | G15: 3516536874 | H15: Recomendación | I15: Obra social | J15: CPCE | R15: =IF(H15="","",VLOOKUP(H15,'Hoja 9'!$A$1:$B$255,2,0)) -> BOCA EN BOCA | S15: =IF(A15="","",YEAR(A15)) -> 2022 | T15: =IF(A15="","",MONTH(A15)) -> 11
A16: 44891.475 | B16: Andino | C16: Guillermo Regino | D16: puchiandino1@gmail.com | E16: 37207 | F16: 43693789 | G16: 3517014316 | H16: Recomendación | I16: Obra social | J16: DASPU | R16: =IF(H16="","",VLOOKUP(H16,'Hoja 9'!$A$1:$B$255,2,0)) -> BOCA EN BOCA | S16: =IF(A16="","",YEAR(A16)) -> 2022 | T16: =IF(A16="","",MONTH(A16)) -> 11
A17: 44893.471 | B17: MUÑOZ | C17: Emery omar | D17: escribaniamunoz@gmail.com | E17: 28950 | F17: 27303587 | G17: 3513493623 | H17: Voy al gym Manantial | I17: Obra social | J17: CAJA NOTARIAL | R17: =IF(H17="","",VLOOKUP(H17,'Hoja 9'!$A$1:$B$255,2,0)) -> GIMNASIO | S17: =IF(A17="","",YEAR(A17)) -> 2022 | T17: =IF(A17="","",MONTH(A17)) -> 11
A18: 44893.501 | B18: Boasso | C18: Lucas | D18: sosamariapia@hotmail.com | E18: 42410 | F18: 55011829 | G18: 3516280350 | H18: Google | I18: Obra social | J18: APROSS | R18: =IF(H18="","",VLOOKUP(H18,'Hoja 9'!$A$1:$B$255,2,0)) -> GOOGLE | S18: =IF(A18="","",YEAR(A18)) -> 2022 | T18: =IF(A18="","",MONTH(A18)) -> 11
A19: 44895.838 | B19: Druetta | C19: Joaquín | D19: joadruetta@gmail.com | E19: 35936 | F19: 4081605 | G19: 3513861638 | H19: Recomendación | I19: Particular | R19: =IF(H19="","",VLOOKUP(H19,'Hoja 9'!$A$1:$B$255,2,0)) -> BOCA EN BOCA | S19: =IF(A19="","",YEAR(A19)) -> 2022 | T19: =IF(A19="","",MONTH(A19)) -> 11
A20: 44897.848 | B20: Hilbe | C20: Estela | D20: Estelahilbe5@hotmail.com | E20: 19420 | F20: 10756516 | G20: 3513123179 | H20: Recomendación | I20: Obra social | J20: Jerarquico salud | R20: =IF(H20="","",VLOOKUP(H20,'Hoja 9'!$A$1:$B$255,2,0)) -> BOCA EN BOCA | S20: =IF(A20="","",YEAR(A20)) -> 2022 | T20: =IF(A20="","",MONTH(A20)) -> 12
A21: 44901.883 | B21: Conrero | C21: Valentino | D21: vconrero@gmail.com | E21: 37698 | F21: 44694075 | G21: 3515290969 | H21: Google | I21: Obra social | J21: Medifé | R21: =IF(H21="","",VLOOKUP(H21,'Hoja 9'!$A$1:$B$255,2,0)) -> GOOGLE | S21: =IF(A21="","",YEAR(A21)) -> 2022 | T21: =IF(A21="","",MONTH(A21)) -> 12
A22: 44902.416 | B22: Gonzalez | C22: Nicolas | D22: Nicomatigonzalez@hotmail.com | E22: 34786 | F22: 38749170 | G22: 3512558234 | H22: Recomendación | I22: Particular | R22: =IF(H22="","",VLOOKUP(H22,'Hoja 9'!$A$1:$B$255,2,0)) -> BOCA EN BOCA | S22: =IF(A22="","",YEAR(A22)) -> 2022 | T22: =IF(A22="","",MONTH(A22)) -> 12
A23: 44907.7 | B23: Araujo | C23: Dora Susana | D23: sietejuana@gmail.com | E23: 16564 | F23: 4647485 | G23: 3513503636 | H23: Recomendación | I23: Obra social | J23: APROSS | R23: =IF(H23="","",VLOOKUP(H23,'Hoja 9'!$A$1:$B$255,2,0)) -> BOCA EN BOCA | S23: =IF(A23="","",YEAR(A23)) -> 2022 | T23: =IF(A23="","",MONTH(A23)) -> 12
A24: 44908.351 | B24: Boasi | C24: Ivana | D24: ivanaboasi@gmail.com | E24: 30556 | F24: 30469315 | G24: 3513732026 | H24: Voy al gym Manantial | I24: Particular | R24: =IF(H24="","",VLOOKUP(H24,'Hoja 9'!$A$1:$B$255,2,0)) -> GIMNASIO | S24: =IF(A24="","",YEAR(A24)) -> 2022 | T24: =IF(A24="","",MONTH(A24)) -> 12
A25: 44908.902 | B25: Ferreyra | C25: Ariel | D25: ariel.jferreyra@gmail.com | E25: ramos | F25: 24356325 | G25: 3516535435 | H25: Recomendación | I25: Obra social | R25: =IF(H25="","",VLOOKUP(H25,'Hoja 9'!$A$1:$B$255,2,0)) -> BOCA EN BOCA | S25: =IF(A25="","",YEAR(A25)) -> 2022 | T25: =IF(A25="","",MONTH(A25)) -> 12
A26: 44909.906 | B26: Baena | C26: Gustavo Ariel | D26: arielbaena@hotmail.com.ar | E26: 26901 | F26: 23440420 | G26: 3516419517 | H26: Recomendación | I26: Obra social | J26: APROSS | R26: =IF(H26="","",VLOOKUP(H26,'Hoja 9'!$A$1:$B$255,2,0)) -> BOCA EN BOCA | S26: =IF(A26="","",YEAR(A26)) -> 2022 | T26: =IF(A26="","",MONTH(A26)) -> 12
A27: 44911.649 | B27: Lozano | C27: Ezequiel | D27: ezelozano7@gmail.com | E27: 34581 | F27: 38412070 | G27: 3517384848 | H27: Recomendación | I27: Particular | R27: =IF(H27="","",VLOOKUP(H27,'Hoja 9'!$A$1:$B$255,2,0)) -> BOCA EN BOCA | S27: =IF(A27="","",YEAR(A27)) -> 2022 | T27: =IF(A27="","",MONTH(A27)) -> 12
A28: 44918.476 | B28: Lazcano | C28: Stella | E28: 16642 | F28: 5210099 | G28: 3512757694 | H28: Google | I28: Obra social | J28: APROSS | R28: =IF(H28="","",VLOOKUP(H28,'Hoja 9'!$A$1:$B$255,2,0)) -> GOOGLE | S28: =IF(A28="","",YEAR(A28)) -> 2022 | T28: =IF(A28="","",MONTH(A28)) -> 12
A29: 44920.965 | B29: Accornero | C29: Ignacio | D29: nachoaccornero@hotmail.com | E29: 35767 | F29: 40815684 | G29: 665987371 | H29: Recomendación | I29: Particular | R29: =IF(H29="","",VLOOKUP(H29,'Hoja 9'!$A$1:$B$255,2,0)) -> BOCA EN BOCA | S29: =IF(A29="","",YEAR(A29)) -> 2022 | T29: =IF(A29="","",MONTH(A29)) -> 12
A30: 44921.73 | B30: Ortelli | C30: Esther | D30: esther.tarantino@hotmail.com | E30: 16144 | F30: 4789045 | G30: 3515306152 | H30: Google | I30: Obra social | J30: CPCE | R30: =IF(H30="","",VLOOKUP(H30,'Hoja 9'!$A$1:$B$255,2,0)) -> GOOGLE | S30: =IF(A30="","",YEAR(A30)) -> 2022 | T30: =IF(A30="","",MONTH(A30)) -> 12
A31: 44923.411 | B31: Sibona | C31: Karina | D31: karinasibona@hotmail.com | E31: 26650 | F31: 22795191 | G31: 3512588741 | H31: Google | I31: Obra social | J31: CPCE | R31: =IF(H31="","",VLOOKUP(H31,'Hoja 9'!$A$1:$B$255,2,0)) -> GOOGLE | S31: =IF(A31="","",YEAR(A31)) -> 2022 | T31: =IF(A31="","",MONTH(A31)) -> 12
A32: 44923.412 | B32: Pepi | C32: Bettina | D32: karinasibona@hotmail.com | E32: 41264 | F32: 52466966 | G32: 3512588741 | H32: Google | I32: Obra social | J32: CPCE | R32: =IF(H32="","",VLOOKUP(H32,'Hoja 9'!$A$1:$B$255,2,0)) -> GOOGLE | S32: =IF(A32="","",YEAR(A32)) -> 2022 | T32: =IF(A32="","",MONTH(A32)) -> 12
A33: 44924.73 | B33: Cardoni | C33: Gino | D33: gino.baret@gmail.com | E33: 31877 | F33: 33117511 | G33: 3512287296 | H33: Recomendación | I33: Particular | R33: =IF(H33="","",VLOOKUP(H33,'Hoja 9'!$A$1:$B$255,2,0)) -> BOCA EN BOCA | S33: =IF(A33="","",YEAR(A33)) -> 2022 | T33: =IF(A33="","",MONTH(A33)) -> 12
A34: 44924.838 | B34: Gutiérrez | C34: Ángela nora | D34: angelanoragutierrez03@gmail.com | E34: 18600 | F34: 6259516 | G34: 3512484269 | H34: Google | I34: Obra social | J34: APROSS | R34: =IF(H34="","",VLOOKUP(H34,'Hoja 9'!$A$1:$B$255,2,0)) -> GOOGLE | S34: =IF(A34="","",YEAR(A34)) -> 2022 | T34: =IF(A34="","",MONTH(A34)) -> 12
A35: 44926.812 | B35: Heredia Pereyra | C35: Mercedes Andrea | D35: mercedesahp@hotmail.com | E35: 29279 | F35: 27955896 | G35: 3513401354 | H35: Recomendación | I35: Obra social | J35: APROSS | R35: =IF(H35="","",VLOOKUP(H35,'Hoja 9'!$A$1:$B$255,2,0)) -> BOCA EN BOCA | S35: =IF(A35="","",YEAR(A35)) -> 2022 | T35: =IF(A35="","",MONTH(A35)) -> 12
A36: 44928.448 | B36: Perini | C36: Leonardo | D36: Lf04_cba@hotmail.com | E36: 32451 | F36: 34069704 | G36: 3512615886 | H36: Google | I36: Particular | R36: =IF(H36="","",VLOOKUP(H36,'Hoja 9'!$A$1:$B$255,2,0)) -> GOOGLE | S36: =IF(A36="","",YEAR(A36)) -> 2023 | T36: =IF(A36="","",MONTH(A36)) -> 1
A37: 44928.826 | B37: Brun | C37: Luciano | D37: lucianobrun@hotmail.com | E37: 29722 | F37: 28850950 | G37: 3513904324 | H37: Voy al gym Manantial | I37: Particular | R37: =IF(H37="","",VLOOKUP(H37,'Hoja 9'!$A$1:$B$255,2,0)) -> GIMNASIO | S37: =IF(A37="","",YEAR(A37)) -> 2023 | T37: =IF(A37="","",MONTH(A37)) -> 1
A38: 44930.686 | B38: Dolivo | C38: Josefina | D38: dolivojosefina@gmail.com | E38: 33208 | F38: 35564552 | G38: 3525454941 | H38: Recomendación | I38: Obra social | J38: SANCOR | R38: =IF(H38="","",VLOOKUP(H38,'Hoja 9'!$A$1:$B$255,2,0)) -> BOCA EN BOCA | S38: =IF(A38="","",YEAR(A38)) -> 2023 | T38: =IF(A38="","",MONTH(A38)) -> 1
A39: 44930.971 | B39: LASTRA | C39: MELISA | D39: MELISALASTRA@GMAIL.COM | E39: 32449 | F39: 33976093 | G39: 3512441614 | H39: Voy al gym Manantial | I39: Obra social | J39: A.P.M | R39: =IF(H39="","",VLOOKUP(H39,'Hoja 9'!$A$1:$B$255,2,0)) -> GIMNASIO | S39: =IF(A39="","",YEAR(A39)) -> 2023 | T39: =IF(A39="","",MONTH(A39)) -> 1
A40: 44932.671 | B40: Menzi | C40: Antonio | D40: tony.menzi@gmail.com | E40: 35720 | F40: 40686489 | G40: 3512064245 | H40: Cartilla Obra Social | I40: Obra social | J40: PREVENCIÓN | R40: =IF(H40="","",VLOOKUP(H40,'Hoja 9'!$A$1:$B$255,2,0)) -> OBRA SOCIAL | S40: =IF(A40="","",YEAR(A40)) -> 2023 | T40: =IF(A40="","",MONTH(A40)) -> 1
...

Sheet Contacto
A1: Name | B1: Phone 1 - Value | C1: Estado de contacto | D1: DETALLE_ERROR
A2: {=IF(INGRESOS_API!P2:P3000="","",INGRESOS_API!P2:P3000)} -> Llanos Cristian | B2: {=IF(INGRESOS_API!G2:G3000="","",IF(LEFT(INGRESOS_API!G2:G3000,4)="+549",INGRESOS_API!G2:G3000,IF(LEFT(INGRESOS_API!G2:G3000,3)="+54","+549"&RIGHT(INGRESOS_API!G2:G3000,LEN(INGRESOS_API!G2:G3000)-4),INGRESOS_API!G2:G3000)))} -> +549518046736 | C2: CREADO
A3: Leiva Nilda Carolina | B3: +549513844529 | C3: CREADO
A4: Far Juan Manuel | B4: +549512006711 | C4: CREADO
A5: Urquía Yohana | B5: +549516299562 | C5: CREADO
A6: Lopez Gonzalo Daniel | B6: +549515186768 | C6: CREADO
A7: Agüero Juan Manuel | B7: +549516219534 | C7: CREADO
A8: Valdez Rubén | B8: +549513374771 | C8: CREADO
A9: Giménez Fernando | B9: +549516953672 | C9: CREADO
A10: JOHNSON GUILLERMO | B10: +549515138062 | C10: CREADO
A11: Carnevale Mariela | B11: +549513040216 | C11: CREADO
A12: Isa Minuet Elías | B12: +549517580512 | C12: CREADO
A13: Ghibaudo Pablo | B13: +549515528353 | C13: CREADO
A14: Asinari Emanuel | B14: +549516098550 | C14: CREADO
... A969: Cabanillas Miguel | B969: +549512441054 | C969: CREADO
A970: Cortez Angelica Nene | B970: #VALUE! | C970: YA_EXISTE
A971: Paulino Sofia | B971: #VALUE! | C971: CREADO
A972: Tobares Regina | B972: +549512665822 | C972: CREADO
A973: Davila Pablo | B973: +549513022880 | C973: YA_EXISTE
A974: Moretto Horacio | B974: +549515505817 | C974: CREADO
A975: VIBERTI Carlos | B975: +549514590212 | C975: CREADO
A976: Castro Antonia Matilde | B976: +549513565063 | C976: YA_EXISTE
A977: Merdidian Juan Carlos | B977: +549513146903 | C977: CREADO
A978: Barra González Tomás | B978: +549515329797 | C978: CREADO
A979: Blanco Luis Manuel | B979: +549512008982 | C979: CREADO
A980: Bassano Jorge | B980: +549516817829 | C980: CREADO
A981: Navarro Fabian | B981: +549515135709 | C981: CREADO
A982: Gonzalez Mazzoni Octavio | B982: +549512343290 | C982: CREADO
A983: Romero Sergio | B983: +549513218392 | C983: CREADO
... A1547: Acosta Lucas | B1547: +549364222018 | C1547: INCOMPLETO
C1548: INCOMPLETO
C1549: INCOMPLETO
C1550: INCOMPLETO
C1551: INCOMPLETO
C1552: INCOMPLETO
C1553: INCOMPLETO
C1554: INCOMPLETO
C1555: INCOMPLETO
C1556: INCOMPLETO
C1557: INCOMPLETO
...

Sheet INGRESOS_API
A1: submitted_at | B1: apellido | C1: nombre | D1: email | E1: fecha_nacimiento | F1: dni | G1: telefono_e164 | H1: fuente | I1: tipo_atencion | J1: obra_social | K1: actividad_fisica | L1: actividad_detalle | M1: frecuencia_semana | N1: anio | O1: mes
A2: ='Respuestas de formulario 1'!A2 -> 44865.663 | B2: ='Respuestas de formulario 1'!B2 -> Llanos | C2: ='Respuestas de formulario 1'!C2 -> Cristian | D2: ='Respuestas de formulario 1'!D2 -> Cristian_kobe@hotmail.com | E2: ='Respuestas de formulario 1'!E2 -> 31427 | F2: ='Respuestas de formulario 1'!F2 -> 32099118 | G2: =IFERROR(__xludf.DUMMYFUNCTION("IF('Respuestas de formulario 1'!G2="""","""",IF(LEFT(REGEXREPLACE(TO_TEXT('Respuestas de formulario 1'!G2),""[^0-9]"",""""),2)=""54"",""+""&REGEXREPLACE(TO_TEXT('Respuestas de formulario 1'!G2),""[^0-9]"",""""),""+54""&REGEXREPLACE(TO_TEXT('Respuestas de "&"formulario 1'!G2),""[^0-9]"","""")))"),"+543518046736") -> +543518046736 | H2: ='Respuestas de formulario 1'!S2 -> 2022 | I2: =IFERROR(__xludf.DUMMYFUNCTION("IF('Respuestas de formulario 1'!I2="""","""",TO_TEXT('Respuestas de formulario 1'!I2))"),"Obra social") -> Obra social | J2: =IFERROR(__xludf.DUMMYFUNCTION("IF('Respuestas de formulario 1'!J2<>"""",UPPER(TRIM(TO_TEXT('Respuestas de formulario 1'!J2))),IF('Respuestas de formulario 1'!O2<>"""",UPPER(TRIM(TO_TEXT('Respuestas de formulario 1'!O2))),""""))"),"APROSS") -> APROSS | K2: =IFERROR(__xludf.DUMMYFUNCTION("IF('Respuestas de formulario 1'!K2="""","""",TO_TEXT('Respuestas de formulario 1'!K2))"),"") | L2: =IFERROR(__xludf.DUMMYFUNCTION("IF('Respuestas de formulario 1'!L2="""","""",TO_TEXT('Respuestas de formulario 1'!L2))"),"") | M2: =IFERROR(__xludf.DUMMYFUNCTION("IF('Respuestas de formulario 1'!M2="""","""",TO_TEXT('Respuestas de formulario 1'!M2))"),"") | N2: =IF(A2="","",IFERROR(YEAR(A2),"")) -> 2022 | O2: =IF(A2="","",IFERROR(TEXT(A2,"mmmm"),"")) -> octubre | P2: {=IF(F2:F2000="",,B2:B2000&" "&C2:C2000)} -> Llanos Cristian
A3: ='Respuestas de formulario 1'!A3 -> 44866.425 | B3: ='Respuestas de formulario 1'!B3 -> Leiva | C3: ='Respuestas de formulario 1'!C3 -> Nilda Carolina | D3: ='Respuestas de formulario 1'!D3 -> caroagus023@gmail.com | E3: ='Respuestas de formulario 1'!E3 -> 29208 | F3: ='Respuestas de formulario 1'!F3 -> 27671982 | G3: =IFERROR(__xludf.DUMMYFUNCTION("IF('Respuestas de formulario 1'!G3="""","""",IF(LEFT(REGEXREPLACE(TO_TEXT('Respuestas de formulario 1'!G3),""[^0-9]"",""""),2)=""54"",""+""&REGEXREPLACE(TO_TEXT('Respuestas de formulario 1'!G3),""[^0-9]"",""""),""+54""&REGEXREPLACE(TO_TEXT('Respuestas de "&"formulario 1'!G3),""[^0-9]"","""")))"),"+543513844529") -> +543513844529 | H3: ='Respuestas de formulario 1'!S3 -> 2022 | I3: =IFERROR(__xludf.DUMMYFUNCTION("IF('Respuestas de formulario 1'!I3="""","""",TO_TEXT('Respuestas de formulario 1'!I3))"),"Particular") -> Particular | J3: =IFERROR(__xludf.DUMMYFUNCTION("IF('Respuestas de formulario 1'!J3<>"""",UPPER(TRIM(TO_TEXT('Respuestas de formulario 1'!J3))),IF('Respuestas de formulario 1'!O3<>"""",UPPER(TRIM(TO_TEXT('Respuestas de formulario 1'!O3))),""""))"),"") | K3: =IFERROR(__xludf.DUMMYFUNCTION("IF('Respuestas de formulario 1'!K3="""","""",TO_TEXT('Respuestas de formulario 1'!K3))"),"") | L3: =IFERROR(__xludf.DUMMYFUNCTION("IF('Respuestas de formulario 1'!L3="""","""",TO_TEXT('Respuestas de formulario 1'!L3))"),"") | M3: =IFERROR(__xludf.DUMMYFUNCTION("IF('Respuestas de formulario 1'!M3="""","""",TO_TEXT('Respuestas de formulario 1'!M3))"),"") | N3: =IF(A3="","",IFERROR(YEAR(A3),"")) -> 2022 | O3: =IF(A3="","",IFERROR(TEXT(A3,"mmmm"),"")) -> noviembre | P3: Leiva Nilda Carolina
A4: ='Respuestas de formulario 1'!A4 -> 44872.859 | B4: ='Respuestas de formulario 1'!B4 -> Far | C4: ='Respuestas de formulario 1'!C4 -> Juan Manuel | D4: ='Respuestas de formulario 1'!D4 -> Manufar87@hotmail.com | E4: ='Respuestas de formulario 1'!E4 -> 31894 | F4: ='Respuestas de formulario 1'!F4 -> 33082576 | G4: =IFERROR(__xludf.DUMMYFUNCTION("IF('Respuestas de formulario 1'!G4="""","""",IF(LEFT(REGEXREPLACE(TO_TEXT('Respuestas de formulario 1'!G4),""[^0-9]"",""""),2)=""54"",""+""&REGEXREPLACE(TO_TEXT('Respuestas de formulario 1'!G4),""[^0-9]"",""""),""+54""&REGEXREPLACE(TO_TEXT('Respuestas de "&"formulario 1'!G4),""[^0-9]"","""")))"),"+543512006711") -> +543512006711 | H4: ='Respuestas de formulario 1'!S4 -> 2022 | I4: =IFERROR(__xludf.DUMMYFUNCTION("IF('Respuestas de formulario 1'!I4="""","""",TO_TEXT('Respuestas de formulario 1'!I4))"),"Particular") -> Particular | J4: =IFERROR(__xludf.DUMMYFUNCTION("IF('Respuestas de formulario 1'!J4<>"""",UPPER(TRIM(TO_TEXT('Respuestas de formulario 1'!J4))),IF('Respuestas de formulario 1'!O4<>"""",UPPER(TRIM(TO_TEXT('Respuestas de formulario 1'!O4))),""""))"),"") | K4: =IFERROR(__xludf.DUMMYFUNCTION("IF('Respuestas de formulario 1'!K4="""","""",TO_TEXT('Respuestas de formulario 1'!K4))"),"") | L4: =IFERROR(__xludf.DUMMYFUNCTION("IF('Respuestas de formulario 1'!L4="""","""",TO_TEXT('Respuestas de formulario 1'!L4))"),"") | M4: =IFERROR(__xludf.DUMMYFUNCTION("IF('Respuestas de formulario 1'!M4="""","""",TO_TEXT('Respuestas de formulario 1'!M4))"),"") | N4: =IF(A4="","",IFERROR(YEAR(A4),"")) -> 2022 | O4: =IF(A4="","",IFERROR(TEXT(A4,"mmmm"),"")) -> noviembre | P4: Far Juan Manuel
A5: ='Respuestas de formulario 1'!A5 -> 44879.654 | B5: ='Respuestas de formulario 1'!B5 -> Urquía | C5: ='Respuestas de formulario 1'!C5 -> Yohana | D5: ='Respuestas de formulario 1'!D5 -> yohana.urquia@gmail.com | E5: ='Respuestas de formulario 1'!E5 -> 31206 | F5: ='Respuestas de formulario 1'!F5 -> 31647631 | G5: =IFERROR(__xludf.DUMMYFUNCTION("IF('Respuestas de formulario 1'!G5="""","""",IF(LEFT(REGEXREPLACE(TO_TEXT('Respuestas de formulario 1'!G5),""[^0-9]"",""""),2)=""54"",""+""&REGEXREPLACE(TO_TEXT('Respuestas de formulario 1'!G5),""[^0-9]"",""""),""+54""&REGEXREPLACE(TO_TEXT('Respuestas de "&"formulario 1'!G5),""[^0-9]"","""")))"),"+543516299562") -> +543516299562 | H5: ='Respuestas de formulario 1'!S5 -> 2022 | I5: =IFERROR(__xludf.DUMMYFUNCTION("IF('Respuestas de formulario 1'!I5="""","""",TO_TEXT('Respuestas de formulario 1'!I5))"),"Particular") -> Particular | J5: =IFERROR(__xludf.DUMMYFUNCTION("IF('Respuestas de formulario 1'!J5<>"""",UPPER(TRIM(TO_TEXT('Respuestas de formulario 1'!J5))),IF('Respuestas de formulario 1'!O5<>"""",UPPER(TRIM(TO_TEXT('Respuestas de formulario 1'!O5))),""""))"),"") | K5: =IFERROR(__xludf.DUMMYFUNCTION("IF('Respuestas de formulario 1'!K5="""","""",TO_TEXT('Respuestas de formulario 1'!K5))"),"") | L5: =IFERROR(__xludf.DUMMYFUNCTION("IF('Respuestas de formulario 1'!L5="""","""",TO_TEXT('Respuestas de formulario 1'!L5))"),"") | M5: =IFERROR(__xludf.DUMMYFUNCTION("IF('Respuestas de formulario 1'!M5="""","""",TO_TEXT('Respuestas de formulario 1'!M5))"),"") | N5: =IF(A5="","",IFERROR(YEAR(A5),"")) -> 2022 | O5: =IF(A5="","",IFERROR(TEXT(A5,"mmmm"),"")) -> noviembre | P5: Urquía Yohana
A6: ='Respuestas de formulario 1'!A6 -> 44879.671 | B6: ='Respuestas de formulario 1'!B6 -> Lopez | C6: ='Respuestas de formulario 1'!C6 -> Gonzalo Daniel | D6: ='Respuestas de formulario 1'!D6 -> Zonlopez10@gmail.com | E6: ='Respuestas de formulario 1'!E6 -> 34623 | F6: ='Respuestas de formulario 1'!F6 -> 38501250 | G6: =IFERROR(__xludf.DUMMYFUNCTION("IF('Respuestas de formulario 1'!G6="""","""",IF(LEFT(REGEXREPLACE(TO_TEXT('Respuestas de formulario 1'!G6),""[^0-9]"",""""),2)=""54"",""+""&REGEXREPLACE(TO_TEXT('Respuestas de formulario 1'!G6),""[^0-9]"",""""),""+54""&REGEXREPLACE(TO_TEXT('Respuestas de "&"formulario 1'!G6),""[^0-9]"","""")))"),"+543515186768") -> +543515186768 | H6: ='Respuestas de formulario 1'!S6 -> 2022 | I6: =IFERROR(__xludf.DUMMYFUNCTION("IF('Respuestas de formulario 1'!I6="""","""",TO_TEXT('Respuestas de formulario 1'!I6))"),"Obra social") -> Obra social | J6: =IFERROR(__xludf.DUMMYFUNCTION("IF('Respuestas de formulario 1'!J6<>"""",UPPER(TRIM(TO_TEXT('Respuestas de formulario 1'!J6))),IF('Respuestas de formulario 1'!O6<>"""",UPPER(TRIM(TO_TEXT('Respuestas de formulario 1'!O6))),""""))"),"APROSS") -> APROSS | K6: =IFERROR(__xludf.DUMMYFUNCTION("IF('Respuestas de formulario 1'!K6="""","""",TO_TEXT('Respuestas de formulario 1'!K6))"),"") | L6: =IFERROR(__xludf.DUMMYFUNCTION("IF('Respuestas de formulario 1'!L6="""","""",TO_TEXT('Respuestas de formulario 1'!L6))"),"") | M6: =IFERROR(__xludf.DUMMYFUNCTION("IF('Respuestas de formulario 1'!M6="""","""",TO_TEXT('Respuestas de formulario 1'!M6))"),"") | N6: =IF(A6="","",IFERROR(YEAR(A6),"")) -> 2022 | O6: =IF(A6="","",IFERROR(TEXT(A6,"mmmm"),"")) -> noviembre | P6: Lopez Gonzalo Daniel
A7: ='Respuestas de formulario 1'!A7 -> 44880.471 | B7: ='Respuestas de formulario 1'!B7 -> Agüero | C7: ='Respuestas de formulario 1'!C7 -> Juan Manuel | D7: ='Respuestas de formulario 1'!D7 -> juanmamendiolaza@gmail.com | E7: ='Respuestas de formulario 1'!E7 -> 31846 | F7: ='Respuestas de formulario 1'!F7 -> 32787354 | G7: =IFERROR(__xludf.DUMMYFUNCTION("IF('Respuestas de formulario 1'!G7="""","""",IF(LEFT(REGEXREPLACE(TO_TEXT('Respuestas de formulario 1'!G7),""[^0-9]"",""""),2)=""54"",""+""&REGEXREPLACE(TO_TEXT('Respuestas de formulario 1'!G7),""[^0-9]"",""""),""+54""&REGEXREPLACE(TO_TEXT('Respuestas de "&"formulario 1'!G7),""[^0-9]"","""")))"),"+543516219534") -> +543516219534 | H7: ='Respuestas de formulario 1'!S7 -> 2022 | I7: =IFERROR(__xludf.DUMMYFUNCTION("IF('Respuestas de formulario 1'!I7="""","""",TO_TEXT('Respuestas de formulario 1'!I7))"),"Particular") -> Particular | J7: =IFERROR(__xludf.DUMMYFUNCTION("IF('Respuestas de formulario 1'!J7<>"""",UPPER(TRIM(TO_TEXT('Respuestas de formulario 1'!J7))),IF('Respuestas de formulario 1'!O7<>"""",UPPER(TRIM(TO_TEXT('Respuestas de formulario 1'!O7))),""""))"),"") | K7: =IFERROR(__xludf.DUMMYFUNCTION("IF('Respuestas de formulario 1'!K7="""","""",TO_TEXT('Respuestas de formulario 1'!K7))"),"") | L7: =IFERROR(__xludf.DUMMYFUNCTION("IF('Respuestas de formulario 1'!L7="""","""",TO_TEXT('Respuestas de formulario 1'!L7))"),"") | M7: =IFERROR(__xludf.DUMMYFUNCTION("IF('Respuestas de formulario 1'!M7="""","""",TO_TEXT('Respuestas de formulario 1'!M7))"),"") | N7: =IF(A7="","",IFERROR(YEAR(A7),"")) -> 2022 | O7: =IF(A7="","",IFERROR(TEXT(A7,"mmmm"),"")) -> noviembre | P7: Agüero Juan Manuel
A8: ='Respuestas de formulario 1'!A8 -> 44880.5 | B8: ='Respuestas de formulario 1'!B8 -> Valdez | C8: ='Respuestas de formulario 1'!C8 -> Rubén | D8: ='Respuestas de formulario 1'!D8 -> Rubenavaldez930@gmail.com | E8: ='Respuestas de formulario 1'!E8 -> 34161 | F8: ='Respuestas de formulario 1'!F8 -> 37733188 | G8: =IFERROR(__xludf.DUMMYFUNCTION("IF('Respuestas de formulario 1'!G8="""","""",IF(LEFT(REGEXREPLACE(TO_TEXT('Respuestas de formulario 1'!G8),""[^0-9]"",""""),2)=""54"",""+""&REGEXREPLACE(TO_TEXT('Respuestas de formulario 1'!G8),""[^0-9]"",""""),""+54""&REGEXREPLACE(TO_TEXT('Respuestas de "&"formulario 1'!G8),""[^0-9]"","""")))"),"+543513374771") -> +543513374771 | H8: ='Respuestas de formulario 1'!S8 -> 2022 | I8: =IFERROR(__xludf.DUMMYFUNCTION("IF('Respuestas de formulario 1'!I8="""","""",TO_TEXT('Respuestas de formulario 1'!I8))"),"") | J8: =IFERROR(__xludf.DUMMYFUNCTION("IF('Respuestas de formulario 1'!J8<>"""",UPPER(TRIM(TO_TEXT('Respuestas de formulario 1'!J8))),IF('Respuestas de formulario 1'!O8<>"""",UPPER(TRIM(TO_TEXT('Respuestas de formulario 1'!O8))),""""))"),"APROSS") -> APROSS | K8: =IFERROR(__xludf.DUMMYFUNCTION("IF('Respuestas de formulario 1'!K8="""","""",TO_TEXT('Respuestas de formulario 1'!K8))"),"") | L8: =IFERROR(__xludf.DUMMYFUNCTION("IF('Respuestas de formulario 1'!L8="""","""",TO_TEXT('Respuestas de formulario 1'!L8))"),"") | M8: =IFERROR(__xludf.DUMMYFUNCTION("IF('Respuestas de formulario 1'!M8="""","""",TO_TEXT('Respuestas de formulario 1'!M8))"),"") | N8: =IF(A8="","",IFERROR(YEAR(A8),"")) -> 2022 | O8: =IF(A8="","",IFERROR(TEXT(A8,"mmmm"),"")) -> noviembre | P8: Valdez Rubén
A9: ='Respuestas de formulario 1'!A9 -> 44881.413 | B9: ='Respuestas de formulario 1'!B9 -> Giménez | C9: ='Respuestas de formulario 1'!C9 -> Fernando | D9: ='Respuestas de formulario 1'!D9 -> gimenezfa@gmail.com | E9: ='Respuestas de formulario 1'!E9 -> 35171 | F9: ='Respuestas de formulario 1'!F9 -> 30544064 | G9: =IFERROR(__xludf.DUMMYFUNCTION("IF('Respuestas de formulario 1'!G9="""","""",IF(LEFT(REGEXREPLACE(TO_TEXT('Respuestas de formulario 1'!G9),""[^0-9]"",""""),2)=""54"",""+""&REGEXREPLACE(TO_TEXT('Respuestas de formulario 1'!G9),""[^0-9]"",""""),""+54""&REGEXREPLACE(TO_TEXT('Respuestas de "&"formulario 1'!G9),""[^0-9]"","""")))"),"+543516953672") -> +543516953672 | H9: ='Respuestas de formulario 1'!S9 -> 2022 | I9: =IFERROR(__xludf.DUMMYFUNCTION("IF('Respuestas de formulario 1'!I9="""","""",TO_TEXT('Respuestas de formulario 1'!I9))"),"Obra social") -> Obra social | J9: =IFERROR(__xludf.DUMMYFUNCTION("IF('Respuestas de formulario 1'!J9<>"""",UPPER(TRIM(TO_TEXT('Respuestas de formulario 1'!J9))),IF('Respuestas de formulario 1'!O9<>"""",UPPER(TRIM(TO_TEXT('Respuestas de formulario 1'!O9))),""""))"),"APROSS") -> APROSS | K9: =IFERROR(__xludf.DUMMYFUNCTION("IF('Respuestas de formulario 1'!K9="""","""",TO_TEXT('Respuestas de formulario 1'!K9))"),"") | L9: =IFERROR(__xludf.DUMMYFUNCTION("IF('Respuestas de formulario 1'!L9="""","""",TO_TEXT('Respuestas de formulario 1'!L9))"),"") | M9: =IFERROR(__xludf.DUMMYFUNCTION("IF('Respuestas de formulario 1'!M9="""","""",TO_TEXT('Respuestas de formulario 1'!M9))"),"") | N9: =IF(A9="","",IFERROR(YEAR(A9),"")) -> 2022 | O9: =IF(A9="","",IFERROR(TEXT(A9,"mmmm"),"")) -> noviembre | P9: Giménez Fernando
A10: ='Respuestas de formulario 1'!A10 -> 44881.491 | B10: ='Respuestas de formulario 1'!B10 -> JOHNSON | C10: ='Respuestas de formulario 1'!C10 -> GUILLERMO | D10: ='Respuestas de formulario 1'!D10 -> guillermorjohnson@gmail.com | E10: ='Respuestas de formulario 1'!E10 -> 26996 | F10: ='Respuestas de formulario 1'!F10 -> 23683982 | G10: =IFERROR(__xludf.DUMMYFUNCTION("IF('Respuestas de formulario 1'!G10="""","""",IF(LEFT(REGEXREPLACE(TO_TEXT('Respuestas de formulario 1'!G10),""[^0-9]"",""""),2)=""54"",""+""&REGEXREPLACE(TO_TEXT('Respuestas de formulario 1'!G10),""[^0-9]"",""""),""+54""&REGEXREPLACE(TO_TEXT('Respuestas "&"de formulario 1'!G10),""[^0-9]"","""")))"),"+543515138062") -> +543515138062 | H10: ='Respuestas de formulario 1'!S10 -> 2022 | I10: =IFERROR(__xludf.DUMMYFUNCTION("IF('Respuestas de formulario 1'!I10="""","""",TO_TEXT('Respuestas de formulario 1'!I10))"),"Obra social") -> Obra social | J10: =IFERROR(__xludf.DUMMYFUNCTION("IF('Respuestas de formulario 1'!J10<>"""",UPPER(TRIM(TO_TEXT('Respuestas de formulario 1'!J10))),IF('Respuestas de formulario 1'!O10<>"""",UPPER(TRIM(TO_TEXT('Respuestas de formulario 1'!O10))),""""))"),"CAJA NOTARIAL") -> CAJA NOTARIAL | K10: =IFERROR(__xludf.DUMMYFUNCTION("IF('Respuestas de formulario 1'!K10="""","""",TO_TEXT('Respuestas de formulario 1'!K10))"),"") | L10: =IFERROR(__xludf.DUMMYFUNCTION("IF('Respuestas de formulario 1'!L10="""","""",TO_TEXT('Respuestas de formulario 1'!L10))"),"") | M10: =IFERROR(__xludf.DUMMYFUNCTION("IF('Respuestas de formulario 1'!M10="""","""",TO_TEXT('Respuestas de formulario 1'!M10))"),"") | N10: =IF(A10="","",IFERROR(YEAR(A10),"")) -> 2022 | O10: =IF(A10="","",IFERROR(TEXT(A10,"mmmm"),"")) -> noviembre | P10: JOHNSON GUILLERMO
A11: ='Respuestas de formulario 1'!A11 -> 44881.688 | B11: ='Respuestas de formulario 1'!B11 -> Carnevale | C11: ='Respuestas de formulario 1'!C11 -> Mariela | D11: ='Respuestas de formulario 1'!D11 -> marielacarnevale533@hotmail.com | E11: ='Respuestas de formulario 1'!E11 -> 29629 | F11: ='Respuestas de formulario 1'!F11 -> 23683982 | G11: =IFERROR(__xludf.DUMMYFUNCTION("IF('Respuestas de formulario 1'!G11="""","""",IF(LEFT(REGEXREPLACE(TO_TEXT('Respuestas de formulario 1'!G11),""[^0-9]"",""""),2)=""54"",""+""&REGEXREPLACE(TO_TEXT('Respuestas de formulario 1'!G11),""[^0-9]"",""""),""+54""&REGEXREPLACE(TO_TEXT('Respuestas "&"de formulario 1'!G11),""[^0-9]"","""")))"),"+543513040216") -> +543513040216 | H11: ='Respuestas de formulario 1'!S11 -> 2022 | I11: =IFERROR(__xludf.DUMMYFUNCTION("IF('Respuestas de formulario 1'!I11="""","""",TO_TEXT('Respuestas de formulario 1'!I11))"),"Particular") -> Particular | J11: =IFERROR(__xludf.DUMMYFUNCTION("IF('Respuestas de formulario 1'!J11<>"""",UPPER(TRIM(TO_TEXT('Respuestas de formulario 1'!J11))),IF('Respuestas de formulario 1'!O11<>"""",UPPER(TRIM(TO_TEXT('Respuestas de formulario 1'!O11))),""""))"),"") | K11: =IFERROR(__xludf.DUMMYFUNCTION("IF('Respuestas de formulario 1'!K11="""","""",TO_TEXT('Respuestas de formulario 1'!K11))"),"") | L11: =IFERROR(__xludf.DUMMYFUNCTION("IF('Respuestas de formulario 1'!L11="""","""",TO_TEXT('Respuestas de formulario 1'!L11))"),"") | M11: =IFERROR(__xludf.DUMMYFUNCTION("IF('Respuestas de formulario 1'!M11="""","""",TO_TEXT('Respuestas de formulario 1'!M11))"),"") | N11: =IF(A11="","",IFERROR(YEAR(A11),"")) -> 2022 | O11: =IF(A11="","",IFERROR(TEXT(A11,"mmmm"),"")) -> noviembre | P11: Carnevale Mariela
A12: ='Respuestas de formulario 1'!A12 -> 44882.46 | B12: ='Respuestas de formulario 1'!B12 -> Isa Minuet | C12: ='Respuestas de formulario 1'!C12 -> Elías | D12: ='Respuestas de formulario 1'!D12 -> eliasisaa@gmail.com | E12: ='Respuestas de formulario 1'!E12 -> 36108 | F12: ='Respuestas de formulario 1'!F12 -> 41019335 | G12: =IFERROR(__xludf.DUMMYFUNCTION("IF('Respuestas de formulario 1'!G12="""","""",IF(LEFT(REGEXREPLACE(TO_TEXT('Respuestas de formulario 1'!G12),""[^0-9]"",""""),2)=""54"",""+""&REGEXREPLACE(TO_TEXT('Respuestas de formulario 1'!G12),""[^0-9]"",""""),""+54""&REGEXREPLACE(TO_TEXT('Respuestas "&"de formulario 1'!G12),""[^0-9]"","""")))"),"+543517580512") -> +543517580512 | H12: ='Respuestas de formulario 1'!S12 -> 2022 | I12: =IFERROR(__xludf.DUMMYFUNCTION("IF('Respuestas de formulario 1'!I12="""","""",TO_TEXT('Respuestas de formulario 1'!I12))"),"Obra social") -> Obra social | J12: =IFERROR(__xludf.DUMMYFUNCTION("IF('Respuestas de formulario 1'!J12<>"""",UPPER(TRIM(TO_TEXT('Respuestas de formulario 1'!J12))),IF('Respuestas de formulario 1'!O12<>"""",UPPER(TRIM(TO_TEXT('Respuestas de formulario 1'!O12))),""""))"),"SANCOR") -> SANCOR | K12: =IFERROR(__xludf.DUMMYFUNCTION("IF('Respuestas de formulario 1'!K12="""","""",TO_TEXT('Respuestas de formulario 1'!K12))"),"") | L12: =IFERROR(__xludf.DUMMYFUNCTION("IF('Respuestas de formulario 1'!L12="""","""",TO_TEXT('Respuestas de formulario 1'!L12))"),"") | M12: =IFERROR(__xludf.DUMMYFUNCTION("IF('Respuestas de formulario 1'!M12="""","""",TO_TEXT('Respuestas de formulario 1'!M12))"),"") | N12: =IF(A12="","",IFERROR(YEAR(A12),"")) -> 2022 | O12: =IF(A12="","",IFERROR(TEXT(A12,"mmmm"),"")) -> noviembre | P12: Isa Minuet Elías
A13: ='Respuestas de formulario 1'!A13 -> 44888.414 | B13: ='Respuestas de formulario 1'!B13 -> Ghibaudo | C13: ='Respuestas de formulario 1'!C13 -> Pablo | D13: ='Respuestas de formulario 1'!D13 -> lic.pabloghibaudo@gmail.com | E13: ='Respuestas de formulario 1'!E13 -> 29137 | F13: ='Respuestas de formulario 1'!F13 -> 27267620 | G13: =IFERROR(__xludf.DUMMYFUNCTION("IF('Respuestas de formulario 1'!G13="""","""",IF(LEFT(REGEXREPLACE(TO_TEXT('Respuestas de formulario 1'!G13),""[^0-9]"",""""),2)=""54"",""+""&REGEXREPLACE(TO_TEXT('Respuestas de formulario 1'!G13),""[^0-9]"",""""),""+54""&REGEXREPLACE(TO_TEXT('Respuestas "&"de formulario 1'!G13),""[^0-9]"","""")))"),"+543515528353") -> +543515528353 | H13: ='Respuestas de formulario 1'!S13 -> 2022 | I13: =IFERROR(__xludf.DUMMYFUNCTION("IF('Respuestas de formulario 1'!I13="""","""",TO_TEXT('Respuestas de formulario 1'!I13))"),"Obra social") -> Obra social | J13: =IFERROR(__xludf.DUMMYFUNCTION("IF('Respuestas de formulario 1'!J13<>"""",UPPER(TRIM(TO_TEXT('Respuestas de formulario 1'!J13))),IF('Respuestas de formulario 1'!O13<>"""",UPPER(TRIM(TO_TEXT('Respuestas de formulario 1'!O13))),""""))"),"APROSS") -> APROSS | K13: =IFERROR(__xludf.DUMMYFUNCTION("IF('Respuestas de formulario 1'!K13="""","""",TO_TEXT('Respuestas de formulario 1'!K13))"),"") | L13: =IFERROR(__xludf.DUMMYFUNCTION("IF('Respuestas de formulario 1'!L13="""","""",TO_TEXT('Respuestas de formulario 1'!L13))"),"") | M13: =IFERROR(__xludf.DUMMYFUNCTION("IF('Respuestas de formulario 1'!M13="""","""",TO_TEXT('Respuestas de formulario 1'!M13))"),"") | N13: =IF(A13="","",IFERROR(YEAR(A13),"")) -> 2022 | O13: =IF(A13="","",IFERROR(TEXT(A13,"mmmm"),"")) -> noviembre | P13: Ghibaudo Pablo
A14: ='Respuestas de formulario 1'!A14 -> 44889.821 | B14: ='Respuestas de formulario 1'!B14 -> Asinari | C14: ='Respuestas de formulario 1'!C14 -> Emanuel | D14: ='Respuestas de formulario 1'!D14 -> lic.pabloghibaudo@gmail.com | E14: ='Respuestas de formulario 1'!E14 -> 34338 | F14: ='Respuestas de formulario 1'!F14 -> 38001813 | G14: =IFERROR(__xludf.DUMMYFUNCTION("IF('Respuestas de formulario 1'!G14="""","""",IF(LEFT(REGEXREPLACE(TO_TEXT('Respuestas de formulario 1'!G14),""[^0-9]"",""""),2)=""54"",""+""&REGEXREPLACE(TO_TEXT('Respuestas de formulario 1'!G14),""[^0-9]"",""""),""+54""&REGEXREPLACE(TO_TEXT('Respuestas "&"de formulario 1'!G14),""[^0-9]"","""")))"),"+543516098550") -> +543516098550 | H14: ='Respuestas de formulario 1'!S14 -> 2022 | I14: =IFERROR(__xludf.DUMMYFUNCTION("IF('Respuestas de formulario 1'!I14="""","""",TO_TEXT('Respuestas de formulario 1'!I14))"),"Particular") -> Particular | J14: =IFERROR(__xludf.DUMMYFUNCTION("IF('Respuestas de formulario 1'!J14<>"""",UPPER(TRIM(TO_TEXT('Respuestas de formulario 1'!J14))),IF('Respuestas de formulario 1'!O14<>"""",UPPER(TRIM(TO_TEXT('Respuestas de formulario 1'!O14))),""""))"),"") | K14: =IFERROR(__xludf.DUMMYFUNCTION("IF('Respuestas de formulario 1'!K14="""","""",TO_TEXT('Respuestas de formulario 1'!K14))"),"") | L14: =IFERROR(__xludf.DUMMYFUNCTION("IF('Respuestas de formulario 1'!L14="""","""",TO_TEXT('Respuestas de formulario 1'!L14))"),"") | M14: =IFERROR(__xludf.DUMMYFUNCTION("IF('Respuestas de formulario 1'!M14="""","""",TO_TEXT('Respuestas de formulario 1'!M14))"),"") | N14: =IF(A14="","",IFERROR(YEAR(A14),"")) -> 2022 | O14: =IF(A14="","",IFERROR(TEXT(A14,"mmmm"),"")) -> noviembre | P14: Asinari Emanuel
A15: ='Respuestas de formulario 1'!A15 -> 44890.799 | B15: ='Respuestas de formulario 1'!B15 -> Rivara | C15: ='Respuestas de formulario 1'!C15 -> Mauro Alejandro | D15: ='Respuestas de formulario 1'!D15 -> rivaramauro@hotmail.com | E15: ='Respuestas de formulario 1'!E15 -> 22514 | F15: ='Respuestas de formulario 1'!F15 -> 14747390 | G15: =IFERROR(__xludf.DUMMYFUNCTION("IF('Respuestas de formulario 1'!G15="""","""",IF(LEFT(REGEXREPLACE(TO_TEXT('Respuestas de formulario 1'!G15),""[^0-9]"",""""),2)=""54"",""+""&REGEXREPLACE(TO_TEXT('Respuestas de formulario 1'!G15),""[^0-9]"",""""),""+54""&REGEXREPLACE(TO_TEXT('Respuestas "&"de formulario 1'!G15),""[^0-9]"","""")))"),"+543516536874") -> +543516536874 | H15: ='Respuestas de formulario 1'!S15 -> 2022 | I15: =IFERROR(__xludf.DUMMYFUNCTION("IF('Respuestas de formulario 1'!I15="""","""",TO_TEXT('Respuestas de formulario 1'!I15))"),"Obra social") -> Obra social | J15: =IFERROR(__xludf.DUMMYFUNCTION("IF('Respuestas de formulario 1'!J15<>"""",UPPER(TRIM(TO_TEXT('Respuestas de formulario 1'!J15))),IF('Respuestas de formulario 1'!O15<>"""",UPPER(TRIM(TO_TEXT('Respuestas de formulario 1'!O15))),""""))"),"CPCE") -> CPCE | K15: =IFERROR(__xludf.DUMMYFUNCTION("IF('Respuestas de formulario 1'!K15="""","""",TO_TEXT('Respuestas de formulario 1'!K15))"),"") | L15: =IFERROR(__xludf.DUMMYFUNCTION("IF('Respuestas de formulario 1'!L15="""","""",TO_TEXT('Respuestas de formulario 1'!L15))"),"") | M15: =IFERROR(__xludf.DUMMYFUNCTION("IF('Respuestas de formulario 1'!M15="""","""",TO_TEXT('Respuestas de formulario 1'!M15))"),"") | N15: =IF(A15="","",IFERROR(YEAR(A15),"")) -> 2022 | O15: =IF(A15="","",IFERROR(TEXT(A15,"mmmm"),"")) -> noviembre | P15: Rivara Mauro Alejandro
A16: ='Respuestas de formulario 1'!A16 -> 44891.475 | B16: ='Respuestas de formulario 1'!B16 -> Andino | C16: ='Respuestas de formulario 1'!C16 -> Guillermo Regino | D16: ='Respuestas de formulario 1'!D16 -> puchiandino1@gmail.com | E16: ='Respuestas de formulario 1'!E16 -> 37207 | F16: ='Respuestas de formulario 1'!F16 -> 43693789 | G16: =IFERROR(__xludf.DUMMYFUNCTION("IF('Respuestas de formulario 1'!G16="""","""",IF(LEFT(REGEXREPLACE(TO_TEXT('Respuestas de formulario 1'!G16),""[^0-9]"",""""),2)=""54"",""+""&REGEXREPLACE(TO_TEXT('Respuestas de formulario 1'!G16),""[^0-9]"",""""),""+54""&REGEXREPLACE(TO_TEXT('Respuestas "&"de formulario 1'!G16),""[^0-9]"","""")))"),"+543517014316") -> +543517014316 | H16: ='Respuestas de formulario 1'!S16 -> 2022 | I16: =IFERROR(__xludf.DUMMYFUNCTION("IF('Respuestas de formulario 1'!I16="""","""",TO_TEXT('Respuestas de formulario 1'!I16))"),"Obra social") -> Obra social | J16: =IFERROR(__xludf.DUMMYFUNCTION("IF('Respuestas de formulario 1'!J16<>"""",UPPER(TRIM(TO_TEXT('Respuestas de formulario 1'!J16))),IF('Respuestas de formulario 1'!O16<>"""",UPPER(TRIM(TO_TEXT('Respuestas de formulario 1'!O16))),""""))"),"DASPU") -> DASPU | K16: =IFERROR(__xludf.DUMMYFUNCTION("IF('Respuestas de formulario 1'!K16="""","""",TO_TEXT('Respuestas de formulario 1'!K16))"),"") | L16: =IFERROR(__xludf.DUMMYFUNCTION("IF('Respuestas de formulario 1'!L16="""","""",TO_TEXT('Respuestas de formulario 1'!L16))"),"") | M16: =IFERROR(__xludf.DUMMYFUNCTION("IF('Respuestas de formulario 1'!M16="""","""",TO_TEXT('Respuestas de formulario 1'!M16))"),"") | N16: =IF(A16="","",IFERROR(YEAR(A16),"")) -> 2022 | O16: =IF(A16="","",IFERROR(TEXT(A16,"mmmm"),"")) -> noviembre | P16: Andino Guillermo Regino
A17: ='Respuestas de formulario 1'!A17 -> 44893.471 | B17: ='Respuestas de formulario 1'!B17 -> MUÑOZ | C17: ='Respuestas de formulario 1'!C17 -> Emery omar | D17: ='Respuestas de formulario 1'!D17 -> escribaniamunoz@gmail.com | E17: ='Respuestas de formulario 1'!E17 -> 28950 | F17: ='Respuestas de formulario 1'!F17 -> 27303587 | G17: =IFERROR(__xludf.DUMMYFUNCTION("IF('Respuestas de formulario 1'!G17="""","""",IF(LEFT(REGEXREPLACE(TO_TEXT('Respuestas de formulario 1'!G17),""[^0-9]"",""""),2)=""54"",""+""&REGEXREPLACE(TO_TEXT('Respuestas de formulario 1'!G17),""[^0-9]"",""""),""+54""&REGEXREPLACE(TO_TEXT('Respuestas "&"de formulario 1'!G17),""[^0-9]"","""")))"),"+543513493623") -> +543513493623 | H17: ='Respuestas de formulario 1'!S17 -> 2022 | I17: =IFERROR(__xludf.DUMMYFUNCTION("IF('Respuestas de formulario 1'!I17="""","""",TO_TEXT('Respuestas de formulario 1'!I17))"),"Obra social") -> Obra social | J17: =IFERROR(__xludf.DUMMYFUNCTION("IF('Respuestas de formulario 1'!J17<>"""",UPPER(TRIM(TO_TEXT('Respuestas de formulario 1'!J17))),IF('Respuestas de formulario 1'!O17<>"""",UPPER(TRIM(TO_TEXT('Respuestas de formulario 1'!O17))),""""))"),"CAJA NOTARIAL") -> CAJA NOTARIAL | K17: =IFERROR(__xludf.DUMMYFUNCTION("IF('Respuestas de formulario 1'!K17="""","""",TO_TEXT('Respuestas de formulario 1'!K17))"),"") | L17: =IFERROR(__xludf.DUMMYFUNCTION("IF('Respuestas de formulario 1'!L17="""","""",TO_TEXT('Respuestas de formulario 1'!L17))"),"") | M17: =IFERROR(__xludf.DUMMYFUNCTION("IF('Respuestas de formulario 1'!M17="""","""",TO_TEXT('Respuestas de formulario 1'!M17))"),"") | N17: =IF(A17="","",IFERROR(YEAR(A17),"")) -> 2022 | O17: =IF(A17="","",IFERROR(TEXT(A17,"mmmm"),"")) -> noviembre | P17: MUÑOZ Emery omar
A18: ='Respuestas de formulario 1'!A18 -> 44893.501 | B18: ='Respuestas de formulario 1'!B18 -> Boasso | C18: ='Respuestas de formulario 1'!C18 -> Lucas | D18: ='Respuestas de formulario 1'!D18 -> sosamariapia@hotmail.com | E18: ='Respuestas de formulario 1'!E18 -> 42410 | F18: ='Respuestas de formulario 1'!F18 -> 55011829 | G18: =IFERROR(__xludf.DUMMYFUNCTION("IF('Respuestas de formulario 1'!G18="""","""",IF(LEFT(REGEXREPLACE(TO_TEXT('Respuestas de formulario 1'!G18),""[^0-9]"",""""),2)=""54"",""+""&REGEXREPLACE(TO_TEXT('Respuestas de formulario 1'!G18),""[^0-9]"",""""),""+54""&REGEXREPLACE(TO_TEXT('Respuestas "&"de formulario 1'!G18),""[^0-9]"","""")))"),"+543516280350") -> +543516280350 | H18: ='Respuestas de formulario 1'!S18 -> 2022 | I18: =IFERROR(__xludf.DUMMYFUNCTION("IF('Respuestas de formulario 1'!I18="""","""",TO_TEXT('Respuestas de formulario 1'!I18))"),"Obra social") -> Obra social | J18: =IFERROR(__xludf.DUMMYFUNCTION("IF('Respuestas de formulario 1'!J18<>"""",UPPER(TRIM(TO_TEXT('Respuestas de formulario 1'!J18))),IF('Respuestas de formulario 1'!O18<>"""",UPPER(TRIM(TO_TEXT('Respuestas de formulario 1'!O18))),""""))"),"APROSS") -> APROSS | K18: =IFERROR(__xludf.DUMMYFUNCTION("IF('Respuestas de formulario 1'!K18="""","""",TO_TEXT('Respuestas de formulario 1'!K18))"),"") | L18: =IFERROR(__xludf.DUMMYFUNCTION("IF('Respuestas de formulario 1'!L18="""","""",TO_TEXT('Respuestas de formulario 1'!L18))"),"") | M18: =IFERROR(__xludf.DUMMYFUNCTION("IF('Respuestas de formulario 1'!M18="""","""",TO_TEXT('Respuestas de formulario 1'!M18))"),"") | N18: =IF(A18="","",IFERROR(YEAR(A18),"")) -> 2022 | O18: =IF(A18="","",IFERROR(TEXT(A18,"mmmm"),"")) -> noviembre | P18: Boasso Lucas
A19: ='Respuestas de formulario 1'!A19 -> 44895.838 | B19: ='Respuestas de formulario 1'!B19 -> Druetta | C19: ='Respuestas de formulario 1'!C19 -> Joaquín | D19: ='Respuestas de formulario 1'!D19 -> joadruetta@gmail.com | E19: ='Respuestas de formulario 1'!E19 -> 35936 | F19: ='Respuestas de formulario 1'!F19 -> 4081605 | G19: =IFERROR(__xludf.DUMMYFUNCTION("IF('Respuestas de formulario 1'!G19="""","""",IF(LEFT(REGEXREPLACE(TO_TEXT('Respuestas de formulario 1'!G19),""[^0-9]"",""""),2)=""54"",""+""&REGEXREPLACE(TO_TEXT('Respuestas de formulario 1'!G19),""[^0-9]"",""""),""+54""&REGEXREPLACE(TO_TEXT('Respuestas "&"de formulario 1'!G19),""[^0-9]"","""")))"),"+543513861638") -> +543513861638 | H19: ='Respuestas de formulario 1'!S19 -> 2022 | I19: =IFERROR(__xludf.DUMMYFUNCTION("IF('Respuestas de formulario 1'!I19="""","""",TO_TEXT('Respuestas de formulario 1'!I19))"),"Particular") -> Particular | J19: =IFERROR(__xludf.DUMMYFUNCTION("IF('Respuestas de formulario 1'!J19<>"""",UPPER(TRIM(TO_TEXT('Respuestas de formulario 1'!J19))),IF('Respuestas de formulario 1'!O19<>"""",UPPER(TRIM(TO_TEXT('Respuestas de formulario 1'!O19))),""""))"),"") | K19: =IFERROR(__xludf.DUMMYFUNCTION("IF('Respuestas de formulario 1'!K19="""","""",TO_TEXT('Respuestas de formulario 1'!K19))"),"") | L19: =IFERROR(__xludf.DUMMYFUNCTION("IF('Respuestas de formulario 1'!L19="""","""",TO_TEXT('Respuestas de formulario 1'!L19))"),"") | M19: =IFERROR(__xludf.DUMMYFUNCTION("IF('Respuestas de formulario 1'!M19="""","""",TO_TEXT('Respuestas de formulario 1'!M19))"),"") | N19: =IF(A19="","",IFERROR(YEAR(A19),"")) -> 2022 | O19: =IF(A19="","",IFERROR(TEXT(A19,"mmmm"),"")) -> noviembre | P19: Druetta Joaquín
A20: ='Respuestas de formulario 1'!A20 -> 44897.848 | B20: ='Respuestas de formulario 1'!B20 -> Hilbe | C20: ='Respuestas de formulario 1'!C20 -> Estela | D20: ='Respuestas de formulario 1'!D20 -> Estelahilbe5@hotmail.com | E20: ='Respuestas de formulario 1'!E20 -> 19420 | F20: ='Respuestas de formulario 1'!F20 -> 10756516 | G20: =IFERROR(__xludf.DUMMYFUNCTION("IF('Respuestas de formulario 1'!G20="""","""",IF(LEFT(REGEXREPLACE(TO_TEXT('Respuestas de formulario 1'!G20),""[^0-9]"",""""),2)=""54"",""+""&REGEXREPLACE(TO_TEXT('Respuestas de formulario 1'!G20),""[^0-9]"",""""),""+54""&REGEXREPLACE(TO_TEXT('Respuestas "&"de formulario 1'!G20),""[^0-9]"","""")))"),"+543513123179") -> +543513123179 | H20: ='Respuestas de formulario 1'!S20 -> 2022 | I20: =IFERROR(__xludf.DUMMYFUNCTION("IF('Respuestas de formulario 1'!I20="""","""",TO_TEXT('Respuestas de formulario 1'!I20))"),"Obra social") -> Obra social | J20: =IFERROR(__xludf.DUMMYFUNCTION("IF('Respuestas de formulario 1'!J20<>"""",UPPER(TRIM(TO_TEXT('Respuestas de formulario 1'!J20))),IF('Respuestas de formulario 1'!O20<>"""",UPPER(TRIM(TO_TEXT('Respuestas de formulario 1'!O20))),""""))"),"JERARQUICO SALUD") -> JERARQUICO SALUD | K20: =IFERROR(__xludf.DUMMYFUNCTION("IF('Respuestas de formulario 1'!K20="""","""",TO_TEXT('Respuestas de formulario 1'!K20))"),"") | L20: =IFERROR(__xludf.DUMMYFUNCTION("IF('Respuestas de formulario 1'!L20="""","""",TO_TEXT('Respuestas de formulario 1'!L20))"),"") | M20: =IFERROR(__xludf.DUMMYFUNCTION("IF('Respuestas de formulario 1'!M20="""","""",TO_TEXT('Respuestas de formulario 1'!M20))"),"") | N20: =IF(A20="","",IFERROR(YEAR(A20),"")) -> 2022 | O20: =IF(A20="","",IFERROR(TEXT(A20,"mmmm"),"")) -> diciembre | P20: Hilbe Estela
A21: ='Respuestas de formulario 1'!A21 -> 44901.883 | B21: ='Respuestas de formulario 1'!B21 -> Conrero | C21: ='Respuestas de formulario 1'!C21 -> Valentino | D21: ='Respuestas de formulario 1'!D21 -> vconrero@gmail.com | E21: ='Respuestas de formulario 1'!E21 -> 37698 | F21: ='Respuestas de formulario 1'!F21 -> 44694075 | G21: =IFERROR(__xludf.DUMMYFUNCTION("IF('Respuestas de formulario 1'!G21="""","""",IF(LEFT(REGEXREPLACE(TO_TEXT('Respuestas de formulario 1'!G21),""[^0-9]"",""""),2)=""54"",""+""&REGEXREPLACE(TO_TEXT('Respuestas de formulario 1'!G21),""[^0-9]"",""""),""+54""&REGEXREPLACE(TO_TEXT('Respuestas "&"de formulario 1'!G21),""[^0-9]"","""")))"),"+543515290969") -> +543515290969 | H21: ='Respuestas de formulario 1'!S21 -> 2022 | I21: =IFERROR(__xludf.DUMMYFUNCTION("IF('Respuestas de formulario 1'!I21="""","""",TO_TEXT('Respuestas de formulario 1'!I21))"),"Obra social") -> Obra social | J21: =IFERROR(__xludf.DUMMYFUNCTION("IF('Respuestas de formulario 1'!J21<>"""",UPPER(TRIM(TO_TEXT('Respuestas de formulario 1'!J21))),IF('Respuestas de formulario 1'!O21<>"""",UPPER(TRIM(TO_TEXT('Respuestas de formulario 1'!O21))),""""))"),"MEDIFÉ") -> MEDIFÉ | K21: =IFERROR(__xludf.DUMMYFUNCTION("IF('Respuestas de formulario 1'!K21="""","""",TO_TEXT('Respuestas de formulario 1'!K21))"),"") | L21: =IFERROR(__xludf.DUMMYFUNCTION("IF('Respuestas de formulario 1'!L21="""","""",TO_TEXT('Respuestas de formulario 1'!L21))"),"") | M21: =IFERROR(__xludf.DUMMYFUNCTION("IF('Respuestas de formulario 1'!M21="""","""",TO_TEXT('Respuestas de formulario 1'!M21))"),"") | N21: =IF(A21="","",IFERROR(YEAR(A21),"")) -> 2022 | O21: =IF(A21="","",IFERROR(TEXT(A21,"mmmm"),"")) -> diciembre | P21: Conrero Valentino
A22: ='Respuestas de formulario 1'!A22 -> 44902.416 | B22: ='Respuestas de formulario 1'!B22 -> Gonzalez | C22: ='Respuestas de formulario 1'!C22 -> Nicolas | D22: ='Respuestas de formulario 1'!D22 -> Nicomatigonzalez@hotmail.com | E22: ='Respuestas de formulario 1'!E22 -> 34786 | F22: ='Respuestas de formulario 1'!F22 -> 38749170 | G22: =IFERROR(__xludf.DUMMYFUNCTION("IF('Respuestas de formulario 1'!G22="""","""",IF(LEFT(REGEXREPLACE(TO_TEXT('Respuestas de formulario 1'!G22),""[^0-9]"",""""),2)=""54"",""+""&REGEXREPLACE(TO_TEXT('Respuestas de formulario 1'!G22),""[^0-9]"",""""),""+54""&REGEXREPLACE(TO_TEXT('Respuestas "&"de formulario 1'!G22),""[^0-9]"","""")))"),"+543512558234") -> +543512558234 | H22: ='Respuestas de formulario 1'!S22 -> 2022 | I22: =IFERROR(__xludf.DUMMYFUNCTION("IF('Respuestas de formulario 1'!I22="""","""",TO_TEXT('Respuestas de formulario 1'!I22))"),"Particular") -> Particular | J22: =IFERROR(__xludf.DUMMYFUNCTION("IF('Respuestas de formulario 1'!J22<>"""",UPPER(TRIM(TO_TEXT('Respuestas de formulario 1'!J22))),IF('Respuestas de formulario 1'!O22<>"""",UPPER(TRIM(TO_TEXT('Respuestas de formulario 1'!O22))),""""))"),"") | K22: =IFERROR(__xludf.DUMMYFUNCTION("IF('Respuestas de formulario 1'!K22="""","""",TO_TEXT('Respuestas de formulario 1'!K22))"),"") | L22: =IFERROR(__xludf.DUMMYFUNCTION("IF('Respuestas de formulario 1'!L22="""","""",TO_TEXT('Respuestas de formulario 1'!L22))"),"") | M22: =IFERROR(__xludf.DUMMYFUNCTION("IF('Respuestas de formulario 1'!M22="""","""",TO_TEXT('Respuestas de formulario 1'!M22))"),"") | N22: =IF(A22="","",IFERROR(YEAR(A22),"")) -> 2022 | O22: =IF(A22="","",IFERROR(TEXT(A22,"mmmm"),"")) -> diciembre | P22: Gonzalez Nicolas
A23: ='Respuestas de formulario 1'!A23 -> 44907.7 | B23: ='Respuestas de formulario 1'!B23 -> Araujo | C23: ='Respuestas de formulario 1'!C23 -> Dora Susana | D23: ='Respuestas de formulario 1'!D23 -> sietejuana@gmail.com | E23: ='Respuestas de formulario 1'!E23 -> 16564 | F23: ='Respuestas de formulario 1'!F23 -> 4647485 | G23: =IFERROR(__xludf.DUMMYFUNCTION("IF('Respuestas de formulario 1'!G23="""","""",IF(LEFT(REGEXREPLACE(TO_TEXT('Respuestas de formulario 1'!G23),""[^0-9]"",""""),2)=""54"",""+""&REGEXREPLACE(TO_TEXT('Respuestas de formulario 1'!G23),""[^0-9]"",""""),""+54""&REGEXREPLACE(TO_TEXT('Respuestas "&"de formulario 1'!G23),""[^0-9]"","""")))"),"+543513503636") -> +543513503636 | H23: ='Respuestas de formulario 1'!S23 -> 2022 | I23: =IFERROR(__xludf.DUMMYFUNCTION("IF('Respuestas de formulario 1'!I23="""","""",TO_TEXT('Respuestas de formulario 1'!I23))"),"Obra social") -> Obra social | J23: =IFERROR(__xludf.DUMMYFUNCTION("IF('Respuestas de formulario 1'!J23<>"""",UPPER(TRIM(TO_TEXT('Respuestas de formulario 1'!J23))),IF('Respuestas de formulario 1'!O23<>"""",UPPER(TRIM(TO_TEXT('Respuestas de formulario 1'!O23))),""""))"),"APROSS") -> APROSS | K23: =IFERROR(__xludf.DUMMYFUNCTION("IF('Respuestas de formulario 1'!K23="""","""",TO_TEXT('Respuestas de formulario 1'!K23))"),"") | L23: =IFERROR(__xludf.DUMMYFUNCTION("IF('Respuestas de formulario 1'!L23="""","""",TO_TEXT('Respuestas de formulario 1'!L23))"),"") | M23: =IFERROR(__xludf.DUMMYFUNCTION("IF('Respuestas de formulario 1'!M23="""","""",TO_TEXT('Respuestas de formulario 1'!M23))"),"") | N23: =IF(A23="","",IFERROR(YEAR(A23),"")) -> 2022 | O23: =IF(A23="","",IFERROR(TEXT(A23,"mmmm"),"")) -> diciembre | P23: Araujo Dora Susana
A24: ='Respuestas de formulario 1'!A24 -> 44908.351 | B24: ='Respuestas de formulario 1'!B24 -> Boasi | C24: ='Respuestas de formulario 1'!C24 -> Ivana | D24: ='Respuestas de formulario 1'!D24 -> ivanaboasi@gmail.com | E24: ='Respuestas de formulario 1'!E24 -> 30556 | F24: ='Respuestas de formulario 1'!F24 -> 30469315 | G24: =IFERROR(__xludf.DUMMYFUNCTION("IF('Respuestas de formulario 1'!G24="""","""",IF(LEFT(REGEXREPLACE(TO_TEXT('Respuestas de formulario 1'!G24),""[^0-9]"",""""),2)=""54"",""+""&REGEXREPLACE(TO_TEXT('Respuestas de formulario 1'!G24),""[^0-9]"",""""),""+54""&REGEXREPLACE(TO_TEXT('Respuestas "&"de formulario 1'!G24),""[^0-9]"","""")))"),"+543513732026") -> +543513732026 | H24: ='Respuestas de formulario 1'!S24 -> 2022 | I24: =IFERROR(__xludf.DUMMYFUNCTION("IF('Respuestas de formulario 1'!I24="""","""",TO_TEXT('Respuestas de formulario 1'!I24))"),"Particular") -> Particular | J24: =IFERROR(__xludf.DUMMYFUNCTION("IF('Respuestas de formulario 1'!J24<>"""",UPPER(TRIM(TO_TEXT('Respuestas de formulario 1'!J24))),IF('Respuestas de formulario 1'!O24<>"""",UPPER(TRIM(TO_TEXT('Respuestas de formulario 1'!O24))),""""))"),"") | K24: =IFERROR(__xludf.DUMMYFUNCTION("IF('Respuestas de formulario 1'!K24="""","""",TO_TEXT('Respuestas de formulario 1'!K24))"),"") | L24: =IFERROR(__xludf.DUMMYFUNCTION("IF('Respuestas de formulario 1'!L24="""","""",TO_TEXT('Respuestas de formulario 1'!L24))"),"") | M24: =IFERROR(__xludf.DUMMYFUNCTION("IF('Respuestas de formulario 1'!M24="""","""",TO_TEXT('Respuestas de formulario 1'!M24))"),"") | N24: =IF(A24="","",IFERROR(YEAR(A24),"")) -> 2022 | O24: =IF(A24="","",IFERROR(TEXT(A24,"mmmm"),"")) -> diciembre | P24: Boasi Ivana
A25: ='Respuestas de formulario 1'!A25 -> 44908.902 | B25: ='Respuestas de formulario 1'!B25 -> Ferreyra | C25: ='Respuestas de formulario 1'!C25 -> Ariel | D25: ='Respuestas de formulario 1'!D25 -> ariel.jferreyra@gmail.com | E25: ='Respuestas de formulario 1'!E25 -> ramos | F25: ='Respuestas de formulario 1'!F25 -> 24356325 | G25: =IFERROR(__xludf.DUMMYFUNCTION("IF('Respuestas de formulario 1'!G25="""","""",IF(LEFT(REGEXREPLACE(TO_TEXT('Respuestas de formulario 1'!G25),""[^0-9]"",""""),2)=""54"",""+""&REGEXREPLACE(TO_TEXT('Respuestas de formulario 1'!G25),""[^0-9]"",""""),""+54""&REGEXREPLACE(TO_TEXT('Respuestas "&"de formulario 1'!G25),""[^0-9]"","""")))"),"+543516535435") -> +543516535435 | H25: ='Respuestas de formulario 1'!S25 -> 2022 | I25: =IFERROR(__xludf.DUMMYFUNCTION("IF('Respuestas de formulario 1'!I25="""","""",TO_TEXT('Respuestas de formulario 1'!I25))"),"Obra social") -> Obra social | J25: =IFERROR(__xludf.DUMMYFUNCTION("IF('Respuestas de formulario 1'!J25<>"""",UPPER(TRIM(TO_TEXT('Respuestas de formulario 1'!J25))),IF('Respuestas de formulario 1'!O25<>"""",UPPER(TRIM(TO_TEXT('Respuestas de formulario 1'!O25))),""""))"),"") | K25: =IFERROR(__xludf.DUMMYFUNCTION("IF('Respuestas de formulario 1'!K25="""","""",TO_TEXT('Respuestas de formulario 1'!K25))"),"") | L25: =IFERROR(__xludf.DUMMYFUNCTION("IF('Respuestas de formulario 1'!L25="""","""",TO_TEXT('Respuestas de formulario 1'!L25))"),"") | M25: =IFERROR(__xludf.DUMMYFUNCTION("IF('Respuestas de formulario 1'!M25="""","""",TO_TEXT('Respuestas de formulario 1'!M25))"),"") | N25: =IF(A25="","",IFERROR(YEAR(A25),"")) -> 2022 | O25: =IF(A25="","",IFERROR(TEXT(A25,"mmmm"),"")) -> diciembre | P25: Ferreyra Ariel
A26: ='Respuestas de formulario 1'!A26 -> 44909.906 | B26: ='Respuestas de formulario 1'!B26 -> Baena | C26: ='Respuestas de formulario 1'!C26 -> Gustavo Ariel | D26: ='Respuestas de formulario 1'!D26 -> arielbaena@hotmail.com.ar | E26: ='Respuestas de formulario 1'!E26 -> 26901 | F26: ='Respuestas de formulario 1'!F26 -> 23440420 | G26: =IFERROR(__xludf.DUMMYFUNCTION("IF('Respuestas de formulario 1'!G26="""","""",IF(LEFT(REGEXREPLACE(TO_TEXT('Respuestas de formulario 1'!G26),""[^0-9]"",""""),2)=""54"",""+""&REGEXREPLACE(TO_TEXT('Respuestas de formulario 1'!G26),""[^0-9]"",""""),""+54""&REGEXREPLACE(TO_TEXT('Respuestas "&"de formulario 1'!G26),""[^0-9]"","""")))"),"+543516419517") -> +543516419517 | H26: ='Respuestas de formulario 1'!S26 -> 2022 | I26: =IFERROR(__xludf.DUMMYFUNCTION("IF('Respuestas de formulario 1'!I26="""","""",TO_TEXT('Respuestas de formulario 1'!I26))"),"Obra social") -> Obra social | J26: =IFERROR(__xludf.DUMMYFUNCTION("IF('Respuestas de formulario 1'!J26<>"""",UPPER(TRIM(TO_TEXT('Respuestas de formulario 1'!J26))),IF('Respuestas de formulario 1'!O26<>"""",UPPER(TRIM(TO_TEXT('Respuestas de formulario 1'!O26))),""""))"),"APROSS") -> APROSS | K26: =IFERROR(__xludf.DUMMYFUNCTION("IF('Respuestas de formulario 1'!K26="""","""",TO_TEXT('Respuestas de formulario 1'!K26))"),"") | L26: =IFERROR(__xludf.DUMMYFUNCTION("IF('Respuestas de formulario 1'!L26="""","""",TO_TEXT('Respuestas de formulario 1'!L26))"),"") | M26: =IFERROR(__xludf.DUMMYFUNCTION("IF('Respuestas de formulario 1'!M26="""","""",TO_TEXT('Respuestas de formulario 1'!M26))"),"") | N26: =IF(A26="","",IFERROR(YEAR(A26),"")) -> 2022 | O26: =IF(A26="","",IFERROR(TEXT(A26,"mmmm"),"")) -> diciembre | P26: Baena Gustavo Ariel
A27: ='Respuestas de formulario 1'!A27 -> 44911.649 | B27: ='Respuestas de formulario 1'!B27 -> Lozano | C27: ='Respuestas de formulario 1'!C27 -> Ezequiel | D27: ='Respuestas de formulario 1'!D27 -> ezelozano7@gmail.com | E27: ='Respuestas de formulario 1'!E27 -> 34581 | F27: ='Respuestas de formulario 1'!F27 -> 38412070 | G27: =IFERROR(__xludf.DUMMYFUNCTION("IF('Respuestas de formulario 1'!G27="""","""",IF(LEFT(REGEXREPLACE(TO_TEXT('Respuestas de formulario 1'!G27),""[^0-9]"",""""),2)=""54"",""+""&REGEXREPLACE(TO_TEXT('Respuestas de formulario 1'!G27),""[^0-9]"",""""),""+54""&REGEXREPLACE(TO_TEXT('Respuestas "&"de formulario 1'!G27),""[^0-9]"","""")))"),"+543517384848") -> +543517384848 | H27: ='Respuestas de formulario 1'!S27 -> 2022 | I27: =IFERROR(__xludf.DUMMYFUNCTION("IF('Respuestas de formulario 1'!I27="""","""",TO_TEXT('Respuestas de formulario 1'!I27))"),"Particular") -> Particular | J27: =IFERROR(__xludf.DUMMYFUNCTION("IF('Respuestas de formulario 1'!J27<>"""",UPPER(TRIM(TO_TEXT('Respuestas de formulario 1'!J27))),IF('Respuestas de formulario 1'!O27<>"""",UPPER(TRIM(TO_TEXT('Respuestas de formulario 1'!O27))),""""))"),"") | K27: =IFERROR(__xludf.DUMMYFUNCTION("IF('Respuestas de formulario 1'!K27="""","""",TO_TEXT('Respuestas de formulario 1'!K27))"),"") | L27: =IFERROR(__xludf.DUMMYFUNCTION("IF('Respuestas de formulario 1'!L27="""","""",TO_TEXT('Respuestas de formulario 1'!L27))"),"") | M27: =IFERROR(__xludf.DUMMYFUNCTION("IF('Respuestas de formulario 1'!M27="""","""",TO_TEXT('Respuestas de formulario 1'!M27))"),"") | N27: =IF(A27="","",IFERROR(YEAR(A27),"")) -> 2022 | O27: =IF(A27="","",IFERROR(TEXT(A27,"mmmm"),"")) -> diciembre | P27: Lozano Ezequiel
